Workbook

Sheet ID命名規則
A1: 更新履歴
C2: キミコイ_命名規則
C4: 基本ルール
C6: ・大竹さんの取り回ししやすいものが理想ですので、こうしたいなどありましたらお気軽にお申し付けください。
C8: ## 命名規則
C9: ・半角英数字・アンダースコアのみ使用（日本語・スペース・大文字禁止）
C10: ・ui_ bg_ chara_ icon_ fx_ cursor_ bgm_ se_ vo_ cg_ ref_ などプレフィックスをつける
C11: 例: ui_btn_start.png / bg_desktop_01.png / icon_lime_01.png
C13: ・キャラ立ち絵や背景などのイラスト素材は差分の有無に関わらず差分番号と連番を付ける
C14: 例: chara_miyu_01_01（デフォルト表情）, chara_miyu_01_02（笑顔差分）
C15: ・IDを見ただけでどの素材か分かるように心がける
C17: ■主要プレフィックス
C18: ui_：UI全般
... C20: chara_：キャラクター
D21: └_miyu…美結の識別子
D22: └_imo…妹の識別子
C23: fx_：エフェクト
C24: bgm_：バックグラウンドミュージック
C25: se_：サウンドエフェクト
C26: vo_：音声ファイル（ボイス）
C27: cg_：イベントCG
C28: ref_：参考画像・完成図（ゲーム本編で使わない確認用素材）
C29: ■背景
C30: ・bg_(場所)_(差分番号)
D31: 例) bg_classroom_01
D32: ・差分番号は有無関わらず必ず01を付ける
C35: ■キャライラスト
C36: ・chara_(キャラ名)_(連番)_(差分番号)
D37: 例) chara_miyu_01_01 / chara_imo_01_01
D38: ・差分番号は有無関わらず必ず01を付ける
D39: ・連番必須
C41: ■UI
C42: ・ui_(機能/画面)_(部位/種類)_(状態/連番)
D43: 例) ui_lime_icon_01
E44: LIMEの顔アイコン等
D45: 例)ui_kmki_btn_log
E46: キミコイの「ログ」ボタン
D47: 例)ui_popup_exit
E48: ゲーム終了のポップアップ
D49: 例)ui_kmki_choice_on
...

Sheet サマリー
A1: キミコイ素材リスト サマリー
A3: 音声 | F3: イラスト
A4: 総数 | B4: =COUNTA(音声!$B$3:$B$52) -> 50 | F4: 総数 | G4: =COUNTA(イラスト!$B$3:$B$242) -> 240
A5: 取込済 | B5: =COUNTIF(音声!$L$3:$L$52,"〇") -> 50 | F5: 取込済 | G5: =COUNTIF(イラスト!$K$3:$K$242,"〇") -> 234
A6: 未取込 | B6: =COUNTBLANK(音声!$L$3:$L$52) -> 0 | F6: 未取込 | G6: =COUNTBLANK(イラスト!$K$3:$K$242) -> 6
A7: 使用中 | B7: =COUNTIF(音声!$M$3:$M$52,"〇") -> 45 | F7: 使用中 | G7: =COUNTIF(イラスト!$L$3:$L$242,"〇") -> 196
A8: 未使用/未確認 | B8: =COUNTBLANK(音声!$M$3:$M$52) -> 5 | F8: 未使用/未確認 | G8: =COUNTBLANK(イラスト!$L$3:$L$242) -> 44
A9: ループあり | B9: =COUNTIF(音声!$E$3:$E$52,"〇") -> 18 | F9: UI | G9: =COUNTIF(イラスト!$C$3:$C$242,"UI") -> 137
A10: ループなし | B10: =COUNTBLANK(音声!$E$3:$E$52) -> 32 | F10: 背景 | G10: =COUNTIF(イラスト!$C$3:$C$242,"背景") -> 15
A11: BGM | B11: =COUNTIF(音声!$C$3:$C$52,"BGM") -> 18 | F11: イベントCG | G11: =COUNTIF(イラスト!$C$3:$C$242,"イベントCG") -> 9
A12: SE | B12: =COUNTIF(音声!$C$3:$C$52,"SE") -> 16 | F12: キャラクター | G12: =COUNTIF(イラスト!$C$3:$C$242,"キャラクター") -> 32
A13: VOICE | B13: =COUNTIF(音声!$C$3:$C$52,"VOICE") -> 16 | F13: エフェクト | G13: =COUNTIF(イラスト!$C$3:$C$242,"エフェクト") -> 20
A14: 命名要修正 | B14: =COUNTIF(音声!$F$3:$F$52,"命名要修正") -> 49 | F14: 参考画像 | G14: =COUNTIF(イラスト!$C$3:$C$242,"参考画像") -> 18
A15: Unityのみ/命名要修正 | B15: =COUNTIF(音声!$F$3:$F$52,"Unityのみ/命名要修正") -> 1 | F15: デスクトップ/Googru | G15: =COUNTIF(イラスト!$C$3:$C$242,"デスクトップ/Googru") -> 7
A16: ステータス未取込 | B16: =COUNTIF(音声!$F$3:$F$52,"未取込") -> 0 | F16: ロゴ | G16: =COUNTIF(イラスト!$C$3:$C$242,"ロゴ") -> 2
A17: OK | B17: =COUNTIF(音声!$F$3:$F$52,"OK") -> 0 | F17: 命名要修正 | G17: =COUNTIF(イラスト!$E$3:$E$242,"命名要修正") -> 212
F18: Unityのみ/命名要修正 | G18: =COUNTIF(イラスト!$E$3:$E$242,"Unityのみ/命名要修正") -> 22
F19: ステータス未取込 | G19: =COUNTIF(イラスト!$E$3:$E$242,"未取込") -> 6
F20: OK | G20: =COUNTIF(イラスト!$E$3:$E$242,"OK") -> 0
A23: 対象範囲 | B23: 音声!A2:O52 | F23: 対象範囲 | G23: イラスト!A2:N242

Sheet 音声
A2: No. | B2: ID | C2: 区分 | D2: 使用想定 | E2: ループ | F2: ステータス | G2: 更新日 | H2: 現在のファイル名 | I2: 推奨ID | J2: 元フォルダ | K2: Unity内パス | L2: Unity取込済 | M2: Unity使用中 | N2: 使用箇所 | O2: 備考
A3: 1 | B3: 0.君と恋する１０日間。 | C3: BGM | D3: キミコイADV BGM: title | E3: 〇 | F3: 命名要修正 | G3: 2026-04-28 | H3: 0.君と恋する１０日間。.wav | I3: bgm_title_01 | J3: Resource/sound/BGM/0.君と恋する１０日間。.wav | K3: Horage/Assets/Audio/BGM/0.君と恋する１０日間。.wav | L3: 〇 | M3: 〇 | N3: キミコイADVのBGMキュー（BGM_TITLE、master_scenario_01_初回DAY1.csv 5行目）
A4: 2 | B4: 1.十日参り | C4: BGM | D4: キミコイADV BGM: toka_mairi | E4: 〇 | F4: 命名要修正 | G4: 2026-04-28 | H4: 1.十日参り.wav | I4: bgm_toka_mairi_01 | J4: Resource/sound/BGM/1.十日参り.wav | K4: Horage/Assets/Audio/BGM/1.十日参り.wav | L4: 〇 | M4: 〇 | N4: キミコイADVのBGMキュー（BGM_十日参り、master_scenario_01_初回DAY1.csv 104行目）
A5: 3 | B5: 1.十日参り_noise | C5: BGM | D5: キミコイADV BGM: toka_mairi_noise | E5: 〇 | F5: 命名要修正 | G5: 2026-05-22 | H5: 1.十日参り_noise.wav | I5: bgm_toka_mairi_noise_01 | J5: Resource/sound/BGM/1.十日参り_noise.wav | K5: Horage/Assets/Audio/BGM/1.十日参り_noise.wav | L5: 〇 | M5: 〇 | N5: キミコイADVのBGMキュー（BGM_十日参り、master_scenario_01_初回DAY1.csv 104行目）
A6: 4 | B6: 10,sound_skipping_lv2 | C6: BGM | D6: キミコイADV BGM: skipping_lv2 | E6: 〇 | F6: 命名要修正 | G6: 2026-05-25 | H6: 10,sound_skipping_lv2.wav | I6: bgm_skipping_lv2_01 | J6: Resource/sound/BGM/10,sound_skipping_lv2.wav | K6: Horage/Assets/Audio/BGM/10,sound_skipping_lv2.wav | L6: 〇 | M6: 〇 | N6: キミコイADVのBGMキュー（BGM_音飛び深刻化、master_scenario_02_初回DAY２.csv 87行目）
A7: 5 | B7: 2,自宅 | C7: BGM | D7: キミコイADV BGM: home | E7: 〇 | F7: 命名要修正 | G7: 2026-04-28 | H7: 2,自宅.wav | I7: bgm_home_01 | J7: Resource/sound/BGM/2,自宅.wav | K7: Horage/Assets/Audio/BGM/2,自宅.wav | L7: 〇 | M7: 〇 | N7: キミコイADVのBGMキュー（BGM_自宅、master_scenario_01_初回DAY1.csv 123行目）
A8: 6 | B8: 2,自宅_noise | C8: BGM | D8: キミコイADV BGM: home_noise | E8: 〇 | F8: 命名要修正 | G8: 2026-05-22 | H8: 2,自宅_noise.wav | I8: bgm_home_noise_01 | J8: Resource/sound/BGM/2,自宅_noise.wav | K8: Horage/Assets/Audio/BGM/2,自宅_noise.wav | L8: 〇 | M8: 〇 | N8: キミコイADVのBGMキュー（BGM_自宅、master_scenario_01_初回DAY1.csv 123行目）
A9: 7 | B9: 3,教室 | C9: BGM | D9: キミコイADV BGM: classroom | E9: 〇 | F9: 命名要修正 | G9: 2026-04-28 | H9: 3,教室.wav | I9: bgm_classroom_01 | J9: Resource/sound/BGM/3,教室.wav | K9: Horage/Assets/Audio/BGM/3,教室.wav | L9: 〇 | M9: 〇 | N9: キミコイADVのBGMキュー（BGM_教室、master_scenario_02_初回DAY２.csv 5行目）
A10: 8 | B10: 3,教室_noise | C10: BGM | D10: キミコイADV BGM: classroom_noise | E10: 〇 | F10: 命名要修正 | G10: 2026-05-22 | H10: 3,教室_noise.wav | I10: bgm_classroom_noise_01 | J10: Resource/sound/BGM/3,教室_noise.wav | K10: Horage/Assets/Audio/BGM/3,教室_noise.wav | L10: 〇 | M10: 〇 | N10: キミコイADVのBGMキュー（BGM_教室、master_scenario_02_初回DAY２.csv 5行目）
A11: 9 | B11: 4,市街地 | C11: BGM | D11: キミコイADV BGM: downtown | E11: 〇 | F11: 命名要修正 | G11: 2026-04-28 | H11: 4,市街地.wav | I11: bgm_downtown_01 | J11: Resource/sound/BGM/4,市街地.wav | K11: Horage/Assets/Audio/BGM/4,市街地.wav | L11: 〇 | M11: 〇 | N11: キミコイADVのBGMキュー（BGM_市街地、master_scenario_02_初回DAY２.csv 29行目）
A12: 10 | B12: 4,市街地_noise | C12: BGM | D12: キミコイADV BGM: downtown_noise | E12: 〇 | F12: 命名要修正 | G12: 2026-05-22 | H12: 4,市街地_noise.wav | I12: bgm_downtown_noise_01 | J12: Resource/sound/BGM/4,市街地_noise.wav | K12: Horage/Assets/Audio/BGM/4,市街地_noise.wav | L12: 〇 | M12: 〇 | N12: キミコイADVのBGMキュー（BGM_市街地、master_scenario_02_初回DAY２.csv 29行目）
A13: 11 | B13: 5,買い物 | C13: BGM | D13: キミコイADV BGM: shopping | E13: 〇 | F13: 命名要修正 | G13: 2026-04-28 | H13: 5,買い物.wav | I13: bgm_shopping_01 | J13: Resource/sound/BGM/5,買い物.wav | K13: Horage/Assets/Audio/BGM/5,買い物.wav | L13: 〇 | M13: 〇 | N13: キミコイADVのBGMキュー（BGM_買い物、master_scenario_03_初回DAY３.csv 10行目）
A14: 12 | B14: 5,買い物_noise | C14: BGM | D14: キミコイADV BGM: shopping_noise | E14: 〇 | F14: 命名要修正 | G14: 2026-05-22 | H14: 5,買い物_noise.wav | I14: bgm_shopping_noise_01 | J14: Resource/sound/BGM/5,買い物_noise.wav | K14: Horage/Assets/Audio/BGM/5,買い物_noise.wav | L14: 〇 | M14: 〇 | N14: キミコイADVのBGMキュー（BGM_買い物、master_scenario_03_初回DAY３.csv 10行目）
... A20: 18 | B20: 9,sound_skipping_lv1 | C20: BGM | D20: キミコイADV BGM: skipping_lv1 | E20: 〇 | F20: 命名要修正 | G20: 2026-05-25 | H20: 9,sound_skipping_lv1.wav | I20: bgm_skipping_lv1_01 | J20: Resource/sound/BGM/9,sound_skipping_lv1.wav | K20: Horage/Assets/Audio/BGM/9,sound_skipping_lv1.wav | L20: 〇 | M20: 〇 | N20: キミコイADVのBGMキュー（BGM_市街地_音飛び、master_scenario_02_初回DAY２.csv 69行目）
A21: 19 | B21: blue_screen_beep | C21: SE | D21: SE: blue_screen_beep | F21: 命名要修正 | G21: 2026-05-16 | H21: blue_screen_beep.wav | I21: se_blue_screen_beep | J21: Resource/sound/SE/blue_screen_beep.wav | K21: Horage/Assets/Audio/SE/blue_screen_beep.wav | L21: 〇 | M21: 〇 | N21: 妹ホラー急拡大・ブルスク演出設定
A22: 20 | B22: keybord1 | C22: SE | D22: SE: keybord1 | F22: 命名要修正 | G22: 2026-05-25 | H22: keybord1.wav | I22: se_keyboard_01 | J22: Resource/sound/SE/keybord1.wav | K22: Horage/Assets/Audio/SE/keybord1.wav | L22: 〇 | M22: 〇 | N22: デスクトップ設定（DesktopShellSettings.asset）
A23: 21 | B23: keybord2 | C23: SE | D23: SE: keybord2 | F23: 命名要修正 | G23: 2026-05-25 | H23: keybord2.wav | I23: se_keyboard_02 | J23: Resource/sound/SE/keybord2.wav | K23: Horage/Assets/Audio/SE/keybord2.wav | L23: 〇 | M23: 〇 | N23: デスクトップ設定（DesktopShellSettings.asset）
A24: 22 | B24: kimikoi_button_mouseon | C24: SE | D24: SE: kimikoi_button_mouseon | F24: 命名要修正 | G24: 2026-05-13 | H24: kimikoi_button_mouseon.mp3 | I24: se_kimikoi_button_mouseover | J24: Resource/sound/SE/kimikoi_button_mouseon.mp3 | K24: Horage/Assets/Audio/SE/kimikoi_button_mouseon.mp3 | L24: 〇 | N24: SE_kimikoi_button_mouseon のキュー名は定義あり。ただし現在のUnityファイルGUID参照なし | O24: キュー定義のGUIDが現ファイルと不一致の可能性
A25: 23 | B25: kimikoi_button_push | C25: SE | D25: SE: kimikoi_button_push | F25: 命名要修正 | G25: 2026-05-13 | H25: kimikoi_button_push.mp3 | I25: se_kimikoi_button_push | J25: Resource/sound/SE/kimikoi_button_push.mp3 | K25: Horage/Assets/Audio/SE/kimikoi_button_push.mp3 | L25: 〇 | N25: SE_kimikoi_button_push のキュー名は定義あり。ただし現在のUnityファイルGUID参照なし | O25: キュー定義のGUIDが現ファイルと不一致の可能性
A26: 24 | B26: lime_boot | C26: SE | D26: SE: lime_boot | F26: 命名要修正 | G26: 2026-05-14 | H26: lime_boot.mp3 | I26: se_lime_boot | J26: Resource/sound/SE/lime_boot.mp3 | K26: Horage/Assets/Audio/SE/lime_boot.mp3 | L26: 〇 | M26: 〇 | N26: キミコイADVのSEキュー（SE_lime_boot、KimikoiAdvHeaderAndAudioData.asset）
A27: 25 | B27: lime_notification | C27: SE | D27: SE: lime_notification | F27: 命名要修正 | G27: 2026-05-14 | H27: lime_notification.mp3 | I27: se_lime_notification | J27: Resource/sound/SE/lime_notification.mp3 | K27: Horage/Assets/Audio/SE/lime_notification.mp3 | L27: 〇 | M27: 〇 | N27: キミコイADVのSEキュー（SE_lime_notification、KimikoiAdvHeaderAndAudioData.asset）
A28: 26 | B28: lime_send | C28: SE | D28: SE: lime_send | F28: 命名要修正 | G28: 2026-05-14 | H28: lime_send.mp3 | I28: se_lime_send | J28: Resource/sound/SE/lime_send.mp3 | K28: Horage/Assets/Audio/SE/lime_send.mp3 | L28: 〇 | M28: 〇 | N28: キミコイADVのSEキュー（SE_lime_send、KimikoiAdvHeaderAndAudioData.asset）
A29: 27 | B29: mouse | C29: SE | D29: SE: mouse | F29: 命名要修正 | G29: 2026-05-25 | H29: mouse.wav | I29: se_mouse_click_01 | J29: Resource/sound/SE/mouse.wav | K29: Horage/Assets/Audio/SE/mouse.wav | L29: 〇 | M29: 〇 | N29: デスクトップ設定（UI_Click.asset）
A30: 28 | B30: noise_Intermittent | C30: SE | D30: SE: noise_Intermittent | F30: 命名要修正 | G30: 2026-05-19 | H30: noise_Intermittent.wav | I30: se_noise_intermittent | J30: Resource/sound/SE/noise_Intermittent.wav | K30: Horage/Assets/Audio/SE/noise_intermittent.wav | L30: 〇 | M30: 〇 | N30: キミコイADVのバグ/グリッチ演出定義
A31: 29 | B31: noise_moment | C31: SE | D31: SE: noise_moment | F31: 命名要修正 | G31: 2026-05-19 | H31: noise_moment.wav | I31: se_noise_moment | J31: Resource/sound/SE/noise_moment.wav | K31: Horage/Assets/Audio/SE/noise_moment.wav | L31: 〇 | M31: 〇 | N31: 妹表示遷移のノイズ演出設定
A32: 30 | B32: noise_sand | C32: SE | D32: SE: noise_sand | F32: 命名要修正 | G32: 2026-05-19 | H32: noise_sand.mp3 | I32: se_noise_sand | J32: Resource/sound/SE/noise_sand.mp3 | K32: Horage/Assets/Audio/SE/noise_sand.mp3 | L32: 〇 | M32: 〇 | N32: 妹ホラー急拡大・ブルスク演出設定
A33: 31 | B33: para_change | C33: SE | D33: SE: para_change | F33: 命名要修正 | G33: 2026-05-25 | H33: para_change.mp3 | I33: se_parameter_change | J33: Resource/sound/SE/para_change.mp3 | K33: Horage/Assets/Audio/SE/para_change.mp3 | L33: 〇 | M33: 〇 | N33: デスクトップ設定（DesktopShellSettings.asset）
A34: 32 | B34: pom | C34: SE | D34: SE: pom | F34: 命名要修正 | G34: 2026-05-12 | H34: pom.mp3 | I34: se_pom_01 | J34: Resource/sound/SE/pom.mp3 | K34: Horage/Assets/Audio/SE/pom.mp3 | L34: 〇 | N34: SE_pom のキュー名は定義あり。ただし現在のUnityファイルGUID参照なし | O34: キュー定義のGUIDが現ファイルと不一致の可能性
A35: 33 | B35: sister_atack | C35: SE | D35: SE: sister_atack | F35: 命名要修正 | G35: 2026-05-16 | H35: sister_atack.wav | I35: se_sister_attack | J35: Resource/sound/SE/sister_atack.wav | K35: Horage/Assets/Audio/SE/sister_atack.wav | L35: 〇 | M35: 〇 | N35: 妹ホラー急拡大・ブルスク演出設定
A36: 34 | B36: sparrow | C36: SE | D36: SE: sparrow | F36: 命名要修正 | G36: 2026-05-12 | H36: sparrow.mp3 | I36: se_sparrow_01 | J36: Resource/sound/SE/sparrow.mp3 | K36: Horage/Assets/Audio/SE/sparrow.mp3 | L36: 〇 | M36: 〇 | N36: キミコイADVのSEキュー（SE_スズメの声、master_scenario_01_初回DAY1.csv 9行目）
A37: 35 | B37: 00-見つけた-妹モックボイス | C37: VOICE | D37: 妹モックボイス: 見つけた | F37: 命名要修正 | G37: 2026-05-21 | H37: 00-見つけた-妹モックボイス.wav | I37: vo_advmock_0010 | J37: Resource/voice/00-見つけた-妹モックボイス.wav | K37: Horage/Assets/Audio/VOICE/AdvMock/00-見つけた-妹モックボイス.wav | L37: 〇 | N37: Unity取込済み。代表的な使用箇所は未確認
A38: 36 | B38: 00-見つけた-妹モックボイス2.0 | C38: VOICE | D38: 妹モックボイス: 見つけた | F38: 命名要修正 | G38: 2026-05-25 | H38: 00-見つけた-妹モックボイス2.0.wav | I38: vo_advmock_0011 | J38: Resource/voice/00-見つけた-妹モックボイス2.0.wav | K38: Horage/Assets/Audio/VOICE/AdvMock/00-見つけた-妹モックボイス2.0.wav | L38: 〇 | M38: 〇 | N38: キミコイADV/REAL_ADVのボイス（VOICE_見つけた、master_scenario_02_初回DAY２.csv 103行目）
A39: 37 | B39: 01-ねえねえ。お兄ちゃんは-妹モックボイス | C39: VOICE | D39: 妹モックボイス: ねえねえ。お兄ちゃんは | F39: 命名要修正 | G39: 2026-05-21 | H39: 01-ねえねえ。お兄ちゃんは-妹モックボイス.wav | I39: vo_advmock_0020 | J39: Resource/voice/01-ねえねえ。お兄ちゃんは-妹モックボイス.wav | K39: Horage/Assets/Audio/VOICE/AdvMock/01-ねえねえ。お兄ちゃんは-妹モックボイス.wav | L39: 〇 | M39: 〇 | N39: キミコイADV/REAL_ADVのボイス（VOICE_ねえねえお兄ちゃんは、master_scenario_02_初回DAY２.csv 104行目）
A40: 38 | B40: 02-わたしをヒロインにしてくれる？-妹モックボイス | C40: VOICE | D40: 妹モックボイス: わたしをヒロインにしてくれる？ | F40: 命名要修正 | G40: 2026-05-21 | H40: 02-わたしをヒロインにしてくれる？-妹モックボイス.wav | I40: vo_advmock_0030 | J40: Resource/voice/02-わたしをヒロインにしてくれる？-妹モックボイス.wav | K40: Horage/Assets/Audio/VOICE/AdvMock/02-わたしをヒロインにしてくれる？-妹モックボイス.wav | L40: 〇 | M40: 〇 | N40: キミコイADV/REAL_ADVのボイス（VOICE_わたしをヒロインにしてくれる、master_scenario_02_初回DAY２.csv 105行目）
A41: 39 | B41: 03-ありがとう-妹モックボイス | C41: VOICE | D41: 妹モックボイス: ありがとう | F41: 命名要修正 | G41: 2026-05-21 | H41: 03-ありがとう-妹モックボイス.wav | I41: vo_advmock_0040 | J41: Resource/voice/03-ありがとう-妹モックボイス.wav | K41: Horage/Assets/Audio/VOICE/AdvMock/03-ありがとう-妹モックボイス.wav | L41: 〇 | M41: 〇 | N41: キミコイADV/REAL_ADVのボイス（VOICE_ありがとう、master_scenario_02_初回DAY２.csv 108行目）
A42: 40 | B42: 04-幸せにしてね、約束だよ-妹モックボイス | C42: VOICE | D42: 妹モックボイス: 幸せにしてね、約束だよ | F42: 命名要修正 | G42: 2026-05-21 | H42: 04-幸せにしてね、約束だよ-妹モックボイス.wav | I42: vo_advmock_0050 | J42: Resource/voice/04-幸せにしてね、約束だよ-妹モックボイス.wav | K42: Horage/Assets/Audio/VOICE/AdvMock/04-幸せにしてね、約束だよ-妹モックボイス.wav | L42: 〇 | M42: 〇 | N42: キミコイADV/REAL_ADVのボイス（VOICE_幸せにしてね約束だよ、master_scenario_02_初回DAY２.csv 109行目）
A43: 41 | B43: 05-やっちゃったね、お兄ちゃん-妹モックボイス | C43: VOICE | D43: 妹モックボイス: やっちゃったね、お兄ちゃん | F43: 命名要修正 | G43: 2026-05-21 | H43: 05-やっちゃったね、お兄ちゃん-妹モックボイス.wav | I43: vo_advmock_0060 | J43: Resource/voice/05-やっちゃったね、お兄ちゃん-妹モックボイス.wav | K43: Horage/Assets/Audio/VOICE/AdvMock/05-やっちゃったね、お兄ちゃん-妹モックボイス.wav | L43: 〇 | M43: 〇 | N43: キミコイADV/REAL_ADVのボイス（VOICE_やっちゃったねお兄ちゃん、master_scenario_03_初回DAY３.csv 78行目）
A44: 42 | B44: 06-あの女ばっかり選んで-妹モックボイス | C44: VOICE | D44: 妹モックボイス: あの女ばっかり選んで | F44: 命名要修正 | G44: 2026-05-21 | H44: 06-あの女ばっかり選んで-妹モックボイス.wav | I44: vo_advmock_0070 | J44: Resource/voice/06-あの女ばっかり選んで-妹モックボイス.wav | K44: Horage/Assets/Audio/VOICE/AdvMock/06-あの女ばっかり選んで-妹モックボイス.wav | L44: 〇 | M44: 〇 | N44: キミコイADV/REAL_ADVのボイス（VOICE_あの女ばっかり選んで、master_scenario_03_初回DAY３.csv 79行目）
A45: 43 | B45: 07-私をヒロインにしてくれないなら-妹モックボイス | C45: VOICE | D45: 妹モックボイス: 私をヒロインにしてくれないなら | F45: 命名要修正 | G45: 2026-05-21 | H45: 07-私をヒロインにしてくれないなら-妹モックボイス.wav | I45: vo_advmock_0080 | J45: Resource/voice/07-私をヒロインにしてくれないなら-妹モックボイス.wav | K45: Horage/Assets/Audio/VOICE/AdvMock/07-私をヒロインにしてくれないなら-妹モックボイス.wav | L45: 〇 | M45: 〇 | N45: キミコイADV/REAL_ADVのボイス（VOICE_ヒロインにしてくれないなら、master_scenario_03_初回DAY３.csv 80行目）
A46: 44 | B46: 08-バイバイ-妹モックボイス | C46: VOICE | D46: 妹モックボイス: バイバイ | F46: 命名要修正 | G46: 2026-05-21 | H46: 08-バイバイ-妹モックボイス.wav | I46: vo_advmock_0090 | J46: Resource/voice/08-バイバイ-妹モックボイス.wav | K46: Horage/Assets/Audio/VOICE/AdvMock/08-バイバイ-妹モックボイス.wav | L46: 〇 | M46: 〇 | N46: キミコイADV/REAL_ADVのボイス（VOICE_バイバイ、master_scenario_03_初回DAY３.csv 81行目）
...

Sheet イラスト
A2: No. | B2: ID | C2: 区分 | D2: 使用想定(画像) | E2: ステータス | F2: 更新日 | G2: 現在のファイル名 | H2: 推奨ID | I2: 元フォルダ | J2: Unity内パス | K2: Unity取込済 | L2: Unity使用中 | M2: 使用箇所 | N2: 備考
A3: 1 | B3: EVCG1 | C3: イベントCG | D3: イベントCG: EVCG1 | E3: 命名要修正 | F3: 2026-05-13 | G3: EVCG1.png | H3: cg_miyu_shrine_01 | I3: Resource/image/EVCG1.png | J3: Horage/Assets/Resources/CG/EVCG1.png | K3: 〇 | L3: 〇 | M3: キミコイADVの立ち絵・EVCG定義
A4: 2 | B4: EVCG1_turn | C4: イベントCG | D4: イベントCG: EVCG1_turn | E4: 命名要修正 | F4: 2026-05-13 | G4: EVCG1_turn.png | H4: cg_miyu_shrine_02 | I4: Resource/image/EVCG1_turn.png | J4: Horage/Assets/Resources/CG/EVCG1_turn.png | K4: 〇 | L4: 〇 | M4: キミコイADVの立ち絵・EVCG定義
A5: 3 | B5: EVCG2_e | C5: イベントCG | D5: イベントCG: EVCG2_e | E5: 命名要修正 | F5: 2026-05-13 | G5: EVCG2_e.png | H5: cg_evcg2_evening_01 | I5: Resource/image/EVCG2_e.png | J5: Horage/Assets/Resources/CG/EVCG2_e.png | K5: 〇 | L5: 〇 | M5: キミコイADVの立ち絵・EVCG定義
A6: 4 | B6: EVCG2_m | C6: イベントCG | D6: イベントCG: EVCG2_m | E6: 命名要修正 | F6: 2026-05-13 | G6: EVCG2_m.png | H6: cg_evcg2_morning_01 | I6: Resource/image/EVCG2_m.png | J6: Horage/Assets/Resources/CG/EVCG2_m.png | K6: 〇 | L6: 〇 | M6: キミコイADVの立ち絵・EVCG定義
A7: 5 | B7: kimikoi_title | C7: UI | D7: UI素材: kimikoi_title | E7: 命名要修正 | F7: 2026-04-30 | G7: kimikoi_title.png | H7: ui_kimikoi_title_logo | I7: Resource/image/kimikoi_title.png | J7: Horage/Assets/Resources/Kimikoi/kimikoi_title.png | K7: 〇 | L7: 〇 | M7: デスクトップPrefab（KimikoiWindow.prefab）
A8: 6 | B8: kimikoi_title_configoff | C8: UI | D8: UI素材: kimikoi_title_configoff | E8: 命名要修正 | F8: 2026-04-30 | G8: kimikoi_title_configoff.png | H8: ui_kimikoi_title_config_off | I8: Resource/image/kimikoi_title_configoff.png | J8: Horage/Assets/Resources/Kimikoi/kimikoi_title_config_off.png | K8: 〇 | L8: 〇 | M8: デスクトップPrefab（KimikoiWindow.prefab）
A9: 7 | B9: kimikoi_title_configon | C9: UI | D9: UI素材: kimikoi_title_configon | E9: 命名要修正 | F9: 2026-04-30 | G9: kimikoi_title_configon.png | H9: ui_kimikoi_title_config_on | I9: Resource/image/kimikoi_title_configon.png | J9: Horage/Assets/Resources/Kimikoi/kimikoi_title_config_on.png | K9: 〇 | L9: 〇 | M9: デスクトップPrefab（KimikoiWindow.prefab）
A10: 8 | B10: kimikoi_title_exitoff | C10: UI | D10: UI素材: kimikoi_title_exitoff | E10: 命名要修正 | F10: 2026-04-30 | G10: kimikoi_title_exitoff.png | H10: ui_kimikoi_title_exit_off | I10: Resource/image/kimikoi_title_exitoff.png | J10: Horage/Assets/Resources/Kimikoi/kimikoi_title_exit_off.png | K10: 〇 | L10: 〇 | M10: デスクトップPrefab（KimikoiWindow.prefab）
A11: 9 | B11: kimikoi_title_exiton | C11: UI | D11: UI素材: kimikoi_title_exiton | E11: 命名要修正 | F11: 2026-04-30 | G11: kimikoi_title_exiton.png | H11: ui_kimikoi_title_exit_on | I11: Resource/image/kimikoi_title_exiton.png | J11: Horage/Assets/Resources/Kimikoi/kimikoi_title_exit_on.png | K11: 〇 | L11: 〇 | M11: デスクトップPrefab（KimikoiWindow.prefab）
A12: 10 | B12: kimikoi_title_startoff | C12: UI | D12: UI素材: kimikoi_title_startoff | E12: 命名要修正 | F12: 2026-04-30 | G12: kimikoi_title_startoff.png | H12: ui_kimikoi_title_start_off | I12: Resource/image/kimikoi_title_startoff.png | J12: Horage/Assets/Resources/Kimikoi/kimikoi_title_start_off.png | K12: 〇 | L12: 〇 | M12: デスクトップPrefab（KimikoiWindow.prefab）
A13: 11 | B13: kimikoi_title_starton | C13: UI | D13: UI素材: kimikoi_title_starton | E13: 命名要修正 | F13: 2026-04-30 | G13: kimikoi_title_starton.png | H13: ui_kimikoi_title_start_on | I13: Resource/image/kimikoi_title_starton.png | J13: Horage/Assets/Resources/Kimikoi/kimikoi_title_start_on.png | K13: 〇 | L13: 〇 | M13: デスクトップPrefab（KimikoiWindow.prefab）
A14: 12 | B14: kimikoi_titleback | C14: 背景 | D14: 背景素材: kimikoi_titleback | E14: 命名要修正 | F14: 2026-04-30 | G14: kimikoi_titleback.jpg | H14: bg_title_01 | I14: Resource/image/kimikoi_titleback.jpg | J14: Horage/Assets/Resources/Reference/Kimikoi/Title/kimikoi_titleback.jpg / Horage/Assets/Resources/Kimikoi/kimikoi_titleback.png | K14: 〇 | L14: 〇 | M14: デスクトップPrefab（KimikoiWindow.prefab） | N14: Unity側重複候補 2件
A15: 13 | B15: lime_comment_me_1 | C15: UI | D15: UI素材: lime_comment_me_1 | E15: 命名要修正 | F15: 2026-05-01 | G15: lime_comment_me_1.png | H15: ui_lime_comment_me_01 | I15: Resource/image/LINE/lime_comment_me_1.png | J15: Horage/Assets/Resources/UI/LIME/lime_comment_me_1.png | K15: 〇 | M15: Unity取込済み。代表的な使用箇所は未確認
A16: 14 | B16: lime_comment_me_2 | C16: UI | D16: UI素材: lime_comment_me_2 | E16: 命名要修正 | F16: 2026-05-01 | G16: lime_comment_me_2.png | H16: ui_lime_comment_me_02 | I16: Resource/image/LINE/lime_comment_me_2.png | J16: Horage/Assets/Resources/UI/LIME/lime_comment_me_2.png | K16: 〇 | L16: 〇 | M16: デスクトップPrefab（LimeWindow.prefab）
A17: 15 | B17: lime_comment_you_1 | C17: UI | D17: UI素材: lime_comment_you_1 | E17: 命名要修正 | F17: 2026-05-01 | G17: lime_comment_you_1.png | H17: ui_lime_comment_you_01 | I17: Resource/image/LINE/lime_comment_you_1.png | J17: Horage/Assets/Resources/UI/LIME/lime_comment_you_1.png | K17: 〇 | M17: Unity取込済み。代表的な使用箇所は未確認
A18: 16 | B18: lime_comment_you_2 | C18: UI | D18: UI素材: lime_comment_you_2 | E18: 命名要修正 | F18: 2026-05-01 | G18: lime_comment_you_2.png | H18: ui_lime_comment_you_02 | I18: Resource/image/LINE/lime_comment_you_2.png | J18: Horage/Assets/Resources/UI/LIME/lime_comment_you_2.png | K18: 〇 | L18: 〇 | M18: デスクトップPrefab（LimeWindow.prefab）
A19: 17 | B19: lime_icon_ootomo | C19: UI | D19: UI素材: lime_icon_ootomo | E19: 命名要修正 | F19: 2026-05-01 | G19: lime_icon_ootomo.png | H19: ui_lime_icon_ootomo | I19: Resource/image/LINE/lime_icon_ootomo.png | J19: Horage/Assets/Resources/UI/LIME/lime_icon_ootomo.png | K19: 〇 | L19: 〇 | M19: デスクトップPrefab（DesktopNotificationRow_Lime.prefab）
A20: 18 | B20: line_choice_1_off | C20: UI | D20: UI素材: line_choice_1_off | E20: 命名要修正 | F20: 2026-05-01 | G20: line_choice_1_off.png | H20: ui_lime_choice_01_off | I20: Resource/image/LINE/line_choice_1_off.png | J20: Horage/Assets/Resources/UI/LIME/line_choice_1_off.png | K20: 〇 | L20: 〇 | M20: デスクトップPrefab（LimeWindow.prefab）
A21: 19 | B21: line_choice_1_on | C21: UI | D21: UI素材: line_choice_1_on | E21: 命名要修正 | F21: 2026-05-01 | G21: line_choice_1_on.png | H21: ui_lime_choice_01_on | I21: Resource/image/LINE/line_choice_1_on.png | J21: Horage/Assets/Resources/UI/LIME/line_choice_1_on.png | K21: 〇 | L21: 〇 | M21: デスクトップPrefab（LimeWindow.prefab）
A22: 20 | B22: line_choice_2_off | C22: UI | D22: UI素材: line_choice_2_off | E22: 命名要修正 | F22: 2026-05-01 | G22: line_choice_2_off.png | H22: ui_lime_choice_02_off | I22: Resource/image/LINE/line_choice_2_off.png | J22: Horage/Assets/Resources/UI/LIME/line_choice_2_off.png | K22: 〇 | L22: 〇 | M22: デスクトップPrefab（LimeWindow.prefab）
A23: 21 | B23: line_choice_2_on | C23: UI | D23: UI素材: line_choice_2_on | E23: 命名要修正 | F23: 2026-05-01 | G23: line_choice_2_on.png | H23: ui_lime_choice_02_on | I23: Resource/image/LINE/line_choice_2_on.png | J23: Horage/Assets/Resources/UI/LIME/line_choice_2_on.png | K23: 〇 | L23: 〇 | M23: デスクトップPrefab（LimeWindow.prefab）
A24: 22 | B24: line_choice_base | C24: UI | D24: UI素材: line_choice_base | E24: 命名要修正 | F24: 2026-05-01 | G24: line_choice_base.png | H24: ui_lime_choice_base | I24: Resource/image/LINE/line_choice_base.png | J24: Horage/Assets/Resources/UI/LIME/line_choice_base.png | K24: 〇 | L24: 〇 | M24: デスクトップPrefab（LimeWindow.prefab）
A25: 23 | B25: line_choice_decoration | C25: UI | D25: UI素材: line_choice_decoration | E25: 命名要修正 | F25: 2026-05-01 | G25: line_choice_decoration.png | H25: ui_lime_choice_decoration | I25: Resource/image/LINE/line_choice_decoration.png | J25: Horage/Assets/Resources/UI/LIME/line_choice_decoration.png | K25: 〇 | L25: 〇 | M25: デスクトップPrefab（LimeWindow.prefab）
A26: 24 | B26: line_choice_input | C26: UI | D26: UI素材: line_choice_input | E26: 命名要修正 | F26: 2026-05-01 | G26: line_choice_input.png | H26: ui_lime_choice_input | I26: Resource/image/LINE/line_choice_input.png | J26: Horage/Assets/Resources/UI/LIME/line_choice_input.png | K26: 〇 | L26: 〇 | M26: Mainシーンに直接参照
A27: 25 | B27: line_choice_plane_off | C27: UI | D27: UI素材: line_choice_plane_off | E27: 命名要修正 | F27: 2026-05-01 | G27: line_choice_plane_off.png | H27: ui_lime_choice_plane_off | I27: Resource/image/LINE/line_choice_plane_off.png | J27: Horage/Assets/Resources/UI/LIME/line_choice_plane_off.png | K27: 〇 | L27: 〇 | M27: デスクトップPrefab（LimeWindow.prefab）
A28: 26 | B28: line_choice_plane_on | C28: UI | D28: UI素材: line_choice_plane_on | E28: 命名要修正 | F28: 2026-05-01 | G28: line_choice_plane_on.png | H28: ui_lime_choice_plane_on | I28: Resource/image/LINE/line_choice_plane_on.png | J28: Horage/Assets/Resources/UI/LIME/line_choice_plane_on.png | K28: 〇 | L28: 〇 | M28: デスクトップPrefab（LimeWindow.prefab）
A29: 27 | B29: line_notification_ootomo | C29: UI | D29: UI素材: line_notification_ootomo | E29: 命名要修正 | F29: 2026-05-01 | G29: line_notification_ootomo.png | H29: ui_lime_notification_ootomo | I29: Resource/image/LINE/line_notification_ootomo.png | J29: Horage/Assets/Resources/UI/LIME/line_notification_ootomo.png | K29: 〇 | L29: 〇 | M29: デスクトップPrefab（LimeWindow.prefab）
A30: 28 | B30: stamp_humu | C30: UI | D30: UI素材: stamp_humu | E30: 未取込 | F30: 2026-05-21 | G30: stamp_humu.png | H30: ui_lime_stamp_humu | I30: Resource/image/LINE/stamp/stamp_humu.png | M30: Unity未取込のため未使用
A31: 29 | B31: stamp_siteyattari | C31: UI | D31: UI素材: stamp_siteyattari | E31: 未取込 | F31: 2026-05-21 | G31: stamp_siteyattari.png | H31: ui_lime_stamp_siteyattari | I31: Resource/image/LINE/stamp/stamp_siteyattari.png | M31: Unity未取込のため未使用
A32: 30 | B32: stamp_umu | C32: UI | D32: UI素材: stamp_umu | E32: 未取込 | F32: 2026-05-21 | G32: stamp_umu.png | H32: ui_lime_stamp_umu | I32: Resource/image/LINE/stamp/stamp_umu.png | M32: Unity未取込のため未使用
A33: 31 | B33: stamp_utagai | C33: UI | D33: UI素材: stamp_utagai | E33: 未取込 | F33: 2026-05-21 | G33: stamp_utagai.png | H33: ui_lime_stamp_utagai | I33: Resource/image/LINE/stamp/stamp_utagai.png | M33: Unity未取込のため未使用
A34: 32 | B34: window_lime | C34: UI | D34: UI素材: window_lime | E34: 命名要修正 | F34: 2026-05-01 | G34: window_lime.png | H34: ui_lime_window_base | I34: Resource/image/LINE/window_lime.png | J34: Horage/Assets/Resources/UI/LIME/window_lime.png | K34: 〇 | L34: 〇 | M34: デスクトップPrefab（LimeWindow.prefab）
A35: 33 | B35: windowcontrol_lime_icon | C35: UI | D35: UI素材: windowcontrol_lime_icon | E35: 命名要修正 | F35: 2026-05-01 | G35: windowcontrol_lime_icon.png | H35: ui_lime_windowcontrol_icon | I35: Resource/image/LINE/windowcontrol_lime_icon.png | J35: Horage/Assets/Resources/UI/LIME/windowcontrol_lime_icon.png | K35: 〇 | L35: 〇 | M35: デスクトップ設定（lime.asset）
A36: 34 | B36: windowcontrol_lime_off | C36: UI | D36: UI素材: windowcontrol_lime_off | E36: 命名要修正 | F36: 2026-05-01 | G36: windowcontrol_lime_off.png | H36: ui_lime_windowcontrol_off | I36: Resource/image/LINE/windowcontrol_lime_off.png | J36: Horage/Assets/Resources/UI/LIME/windowcontrol_lime_off.png | K36: 〇 | L36: 〇 | M36: デスクトップ設定（lime.asset）
A37: 35 | B37: windowcontrol_lime_on | C37: UI | D37: UI素材: windowcontrol_lime_on | E37: 命名要修正 | F37: 2026-05-01 | G37: windowcontrol_lime_on.png | H37: ui_lime_windowcontrol_on | I37: Resource/image/LINE/windowcontrol_lime_on.png | J37: Horage/Assets/Resources/UI/LIME/windowcontrol_lime_on.png | K37: 〇 | L37: 〇 | M37: デスクトップ設定（lime.asset）
A38: 36 | B38: ★完成図(ポップアップ) | C38: 参考画像 | D38: 参考画像/完成図: ★完成図(ポップアップ) | E38: 命名要修正 | F38: 2026-05-01 | G38: ★完成図(ポップアップ).jpg | H38: ref_line_complete_01 | I38: Resource/image/LINE/★完成図(ポップアップ).jpg | J38: Horage/Assets/Resources/Reference/LIME/★完成図(ポップアップ).jpg | K38: 〇 | M38: Unity取込済み。代表的な使用箇所は未確認
A39: 37 | B39: ★完成図(選択肢) | C39: 参考画像 | D39: 参考画像/完成図: ★完成図(選択肢) | E39: 命名要修正 | F39: 2026-05-01 | G39: ★完成図(選択肢).jpg | H39: ref_line_complete_01 | I39: Resource/image/LINE/★完成図(選択肢).jpg | J39: Horage/Assets/Resources/Reference/LIME/★完成図(選択肢).jpg | K39: 〇 | M39: Unity取込済み。代表的な使用箇所は未確認
A40: 38 | B40: ★完成図 | C40: 参考画像 | D40: 参考画像/完成図: ★完成図 | E40: 命名要修正 | F40: 2026-05-01 | G40: ★完成図.jpg | H40: ref_line_complete_01 | I40: Resource/image/LINE/★完成図.jpg | J40: Horage/Assets/Resources/Reference/LIME/★完成図.jpg / Horage/Assets/Resources/Reference/Desktop/★完成図.jpg / Horage/Assets/Resources/Reference/Kimikoi/Main/★完成図.jpg / Horage/Assets/Resources/Reference/Kimikoi/Main/ログ/★完成図.jpg ほか4件 | K40: 〇 | M40: Unity取込済み。代表的な使用箇所は未確認 | N40: Unity側重複候補 8件
A41: 39 | B41: kimikoi_config_base | C41: UI | D41: UI素材: kimikoi_config_base | E41: 命名要修正 | F41: 2026-05-01 | G41: kimikoi_config_base.png | H41: ui_kimikoi_config_base | I41: Resource/image/キミコイコンフィグ画面/kimikoi_config_base.png | J41: Horage/Assets/Resources/Kimikoi/kimikoi_config_base.png | K41: 〇 | L41: 〇 | M41: デスクトップPrefab（KimikoiConfigPhase.prefab）
...
